<mujoco model="g1_29dof scene">
  <include file="g1_29dof.xml"/>

  <statistic center="0 0 0.5" extent="2.0"/>

  <visual>
    <headlight diffuse="0.6 0.6 0.6" ambient="0.3 0.3 0.3" specular="0 0 0"/>
    <rgba haze="0.15 0.25 0.35 1"/>
    <global azimuth="-130" elevation="-20"/>
  </visual>

  <asset>
    <texture type="skybox" builtin="gradient" rgb1="0.3 0.5 0.7" rgb2="0 0 0" width="512" height="3072"/>
  </asset>

  <worldbody>
    <light pos="0 0 1.5" dir="0 0 -1" directional="true"/>
    <body name="platform" pos="0 0 -0.05">
      <joint name="platform_x" type="slide" axis="1 0 0" limited="true" range="-1e-6 1e-6" damping="50"/>
      <joint name="platform_y" type="slide" axis="0 1 0" limited="true" range="-1e-6 1e-6" damping="50"/>
      <geom name="platform" type="box" size="3 3 0.05" mass="10000" rgba="0.2 0.3 0.4 1"/>
    </body>
  </worldbody>
  <actuator>
    <velocity name="platform_x_vel" joint="platform_x" kv="500000"/>
    <velocity name="platform_y_vel" joint="platform_y" kv="500000"/>
  </actuator>
</mujoco>


